Workbook

Sheet Resumen
A1: Sistema de combinadas — Mundial 2026
A2: Base: cuotas de mercado · 14 combinadas (5 anclas, 5 medias, 4 lotería)
A4: TOTALES (en vivo, según tus ediciones)
A5: Apuesta total (S/) | B5: =Sistema!C13+Sistema!C27+Sistema!C41+Sistema!C55+Sistema!C69+Sistema!C88+Sistema!C107+Sistema!C126+Sistema!C145+Sistema!C164+Sistema!C193+Sistema!C222+Sistema!C251+Sistema!C280 -> 245
A6: EV total del portafolio (S/) | B6: =Sistema!C15+Sistema!C29+Sistema!C43+Sistema!C57+Sistema!C71+Sistema!C90+Sistema!C109+Sistema!C128+Sistema!C147+Sistema!C166+Sistema!C195+Sistema!C224+Sistema!C253+Sistema!C282 -> 128.99055
A7: # combinadas con +EV (de 14) | B7: =IF(Sistema!C15>0,1,0)+IF(Sistema!C29>0,1,0)+IF(Sistema!C43>0,1,0)+IF(Sistema!C57>0,1,0)+IF(Sistema!C71>0,1,0)+IF(Sistema!C90>0,1,0)+IF(Sistema!C109>0,1,0)+IF(Sistema!C128>0,1,0)+IF(Sistema!C147>0,1,0)+IF(Sistema!C166>0,1,0)+IF(Sistema!C195>0,1,0)+IF(Sistema!C224>0,1,0)+IF(Sistema!C253>0,1,0)+IF(Sistema!C282>0,1,0) -> 11
A9: BASELINE con probabilidades de mercado (simulación 200k, sin tu ventaja)
A10: P(que alguna combinada gane) | B10: 91.43%
A11: P(la ronda sea rentable, neto>0) | B11: 36.13%
A12: Neto promedio por ronda | B12: S/ -0.16
A13: Apuesta total (provisional) | B13: S/ 245
A15: CÓMO USARLO:
A16: 1) Ve a 'Probabilidades' y ajusta la columna amarilla MI PROB con tu lectura de cada partido.
A17: 2) Mira 'Sistema': las combinadas con EV>0 (¿+EV? = SÍ) son donde tu lectura le gana al mercado.
A18: 3) Ajusta las apuestas (azul) en 'Sistema'. Aquí arriba ves el EV total en vivo.
A19: 4) En vivo usa 'Cashout y Hedge' para decidir cuándo cerrar o asegurar.
A20: NOTA: el baseline de arriba es estático (cuotas de mercado). El EV en vivo usa TU prob.

Sheet Probabilidades
A1: # | B1: Pick | C1: Partido | D1: Cuota | E1: P mercado | F1: MI PROB (editable) | G1: Mi cuota justa | H1: En # combos
A2: 1 | B2: México gana | C2: México vs Sudáfrica | D2: 1.45 | E2: =1/D2 -> 0.68965517 | F2: 0.75 | G2: =1/F2 -> 1.3333333 | H2: 3/14
A3: 2 | B3: Suiza gana | C3: Catar vs Suiza | D3: 1.26 | E3: =1/D3 -> 0.79365079 | F3: 0.87 | G3: =1/F3 -> 1.1494253 | H3: 4/14
A4: 3 | B4: Escocia gana | C4: Haití vs Escocia | D4: 1.47 | E4: =1/D4 -> 0.68027211 | F4: 0.65 | G4: =1/F4 -> 1.5384615 | H4: 2/14
A5: 4 | B5: Turquía gana | C5: Australia vs Turquía | D5: 1.8 | E5: =1/D5 -> 0.55555556 | F5: 0.78 | G5: =1/F5 -> 1.2820513 | H5: 1/14
A6: 5 | B6: Alemania gana | C6: Alemania vs Curazao | D6: 1.05 | E6: =1/D6 -> 0.95238095 | F6: 0.98 | G6: =1/F6 -> 1.0204082 | H6: 6/14
A7: 6 | B7: España gana | C7: España vs Cabo Verde | D7: 1.1 | E7: =1/D7 -> 0.90909091 | F7: 0.98 | G7: =1/F7 -> 1.0204082 | H7: 6/14
A8: 7 | B8: Bélgica o empate (1X) | C8: Bélgica vs Egipto | D8: 1.19 | E8: =1/D8 -> 0.84033613 | F8: 0.77 | G8: =1/F8 -> 1.2987013 | H8: 6/14
A9: 8 | B9: Uruguay gana | C9: Arabia Saudita vs Uruguay | D9: 1.5 | E9: =1/D9 -> 0.66666667 | F9: 0.6667 | G9: =1/F9 -> 1.499925 | H9: 2/14
A10: 9 | B10: Francia gana | C10: Francia vs Senegal | D10: 1.47 | E10: =1/D10 -> 0.68027211 | F10: 0.71 | G10: =1/F10 -> 1.4084507 | H10: 2/14
A11: 10 | B11: Noruega gana | C11: Irak vs Noruega | D11: 1.23 | E11: =1/D11 -> 0.81300813 | F11: 0.87 | G11: =1/F11 -> 1.1494253 | H11: 5/14
A12: 11 | B12: Argentina gana | C12: Argentina vs Argelia | D12: 1.42 | E12: =1/D12 -> 0.70422535 | F12: 0.68 | G12: =1/F12 -> 1.4705882 | H12: 3/14
A13: 12 | B13: Austria gana | C13: Austria vs Jordan | D13: 1.34 | E13: =1/D13 -> 0.74626866 | F13: 0.82 | G13: =1/F13 -> 1.2195122 | H13: 3/14
... A42: 41 | B42: Argentina gana | C42: Jordan vs Argentina | D42: 1.2 | E42: =1/D42 -> 0.83333333 | F42: 0.91 | G42: =1/F42 -> 1.0989011 | H42: 6/14
B44: Edita SOLO la columna amarilla 'MI PROB' con tu lectura de cada partido. Todo lo demás se recalcula solo.

Sheet Sistema
A1: SISTEMA DE COMBINADAS — barra (anclas cortas + medias + lotería)
A2: Apuesta (azul) editable. EV>0 = combinada con valor según TU probabilidad.
A4: COMBINADA A1 · 5 patas
A5: Pick | B5: Partido | C5: Cuota | D5: Mi P
A6: Alemania gana | B6: Alemania vs Curazao | C6: =Probabilidades!D6 -> 1.05 | D6: =Probabilidades!F6 -> 0.98
A7: España gana | B7: España vs Cabo Verde | C7: =Probabilidades!D7 -> 1.1 | D7: =Probabilidades!F7 -> 0.98
A8: Brasil gana | B8: Brasil vs Haití | C8: =Probabilidades!D21 -> 1.06 | D8: =Probabilidades!F21 -> 0.99
A9: España gana | B9: España vs Arabia Saudita | C9: =Probabilidades!D24 -> 1.13 | D9: =Probabilidades!F24 -> 0.885
A10: Francia gana | B10: Francia vs Irak | C10: =Probabilidades!D29 -> 1.12 | D10: =Probabilidades!F29 -> 0.96
A11: Cuota total | C11: =ROUND(PRODUCT(C6:C10),2) -> 1.55
A12: P(gana) según tu prob | C12: =PRODUCT(D6:D10) -> 0.80779628
A13: Apuesta (S/) — editable | C13: 30
A14: Pago si gana (S/) | C14: =C11*C13 -> 46.5
A15: EV (S/) | C15: =C12*C14-C13 -> 7.5625271
A16: ¿+EV? | C16: =IF(C15>0,"SÍ ✓","no") -> SÍ ✓
A18: COMBINADA A2 · 5 patas
A19: Pick | B19: Partido | C19: Cuota | D19: Mi P
A20: Bélgica o empate (1X) | B20: Bélgica vs Egipto | C20: =Probabilidades!D8 -> 1.19 | D20: =Probabilidades!F8 -> 0.77
A21: Suiza o empate (1X) | B21: Suiza vs Bosnia | C21: =Probabilidades!D18 -> 1.17 | D21: =Probabilidades!F18 -> 0.76
A22: Japón o empate (2X) | B22: Túnez vs Japón | C22: =Probabilidades!D23 -> 1.2 | D22: =Probabilidades!F23 -> 0.8333
A23: Egipto o empate (2X) | B23: Nueva Zelanda vs Egipto | C23: =Probabilidades!D27 -> 1.19 | D23: =Probabilidades!F27 -> 0.87
A24: Argelia o empate (2X) | B24: Jordan vs Argelia | C24: =Probabilidades!D30 -> 1.18 | D24: =Probabilidades!F30 -> 0.71
A25: Cuota total | C25: =ROUND(PRODUCT(C20:C24),2) -> 2.35
A26: P(gana) según tu prob | C26: =PRODUCT(D20:D24) -> 0.30121965
A27: Apuesta (S/) — editable | C27: 30
A28: Pago si gana (S/) | C28: =C25*C27 -> 70.5
A29: EV (S/) | C29: =C26*C28-C27 -> -8.7640146
A30: ¿+EV? | C30: =IF(C29>0,"SÍ ✓","no") -> no
A32: COMBINADA A3 · 5 patas
A33: Pick | B33: Partido | C33: Cuota | D33: Mi P
A34: Alemania gana | B34: Alemania vs Curazao | C34: =Probabilidades!D6 -> 1.05 | D34: =Probabilidades!F6 -> 0.98
A35: Noruega gana | B35: Irak vs Noruega | C35: =Probabilidades!D11 -> 1.23 | D35: =Probabilidades!F11 -> 0.87
A36: EE.UU. o empate (1X) | B36: EE.UU. vs Australia | C36: =Probabilidades!D19 -> 1.22 | D36: =Probabilidades!F19 -> 0.68
A37: Inglaterra gana | B37: Panamá vs Inglaterra | C37: =Probabilidades!D41 -> 1.2 | D37: =Probabilidades!F41 -> 0.95
A38: Argentina gana | B38: Jordan vs Argentina | C38: =Probabilidades!D42 -> 1.2 | D38: =Probabilidades!F42 -> 0.91
A39: Cuota total | C39: =ROUND(PRODUCT(C34:C38),2) -> 2.27
A40: P(gana) según tu prob | C40: =PRODUCT(D34:D38) -> 0.50120944
A41: Apuesta (S/) — editable | C41: 30
A42: Pago si gana (S/) | C42: =C39*C41 -> 68.1
A43: EV (S/) | C43: =C40*C42-C41 -> 4.1323626
...

Sheet Cashout y Hedge
A1: Gestión en vivo: Cashout y Cobertura (Hedge)
A3: REGLA DE CASHOUT (heurística)
A4: • El cashout convierte una combinada 'viva' en valor asegurado. Idea: compara lo ofrecido contra lo que esperas si sigues.
A5: • Valor esperado de seguir = (prob. conjunta de las patas restantes) × (pago potencial).
A6: • Cierra (cashout) cuando: el cashout ofrecido ≥ ese valor esperado, O cuando ya asegura tu objetivo de ganancia y no quieres arriesgar.
A7: • Con aversión al riesgo (proteger banca), conviene cerrar ANTES de lo que diría el EV puro.
A8: • Regla práctica simple: si te quedan ≤2 patas y el cashout supera tu umbral de ganancia, cierra.
A10: CALCULADORA DE HEDGE (última pata viva)
A11: Cuando una combinada llega viva a su última pata, puedes asegurar ganancia apostando al resultado contrario.
A13: Pago potencial si gana la combinada (W, S/) | B13: 1000
A14: Cuota del resultado CONTRARIO (o) | B14: 2.5
A15: Lo ya apostado en la combinada (S, S/) | B15: 20
A16: Cuánto apostar al contrario (hedge = W/o) | B16: =B13/B14 -> 400
A17: Ganancia GARANTIZADA pase lo que pase | B17: =B13*(1-1/B14)-B15 -> 580
